
<?xml version="1.0"?>
<robot name="robot_name">
    <material name="blue">
        <color rgba="0.0 0.0 0.8 1"/>
    </material>
    <material name="white">
        <color rgba="1 1 1 1"/>
    </material>
    <material name="black">
        <color rgba="0 0 0 1"/>
    </material>
   <link name="base_link">
    <visual>
        <geometry>
            <cylinder radius="0.2" length="0.6"/>
        </geometry>
        <material name="blue"></material>
    </visual>
    <collision>
        <geometry>
            <cylinder radius="0.2" length="0.6"/>
        </geometry>   
    </collision>
            <inertial>
                <mass value="0.3"/>
                <inertia ixx="0.0003" iyy="0.0003" izz="0.0003" ixy="0" ixz="0" iyz="0"/>
            </inertial>
    </link>

    <link name="right_leg">
        <visual>
            <geometry>
                <box size="0.6 0.1 0.2"/>
            </geometry>
            <origin rpy="0 1.57075 0" xyz="0 0 -0.3"/>
            <material name="white"></material>
        </visual>
    </link>
    
    <link name="left_leg">
        <visual>
            <geometry>
                <box size="0.6 0.1 0.2"/>
            </geometry>
            <origin rpy="0 1.57075 0" xyz="0 0 -0.3"/>
            <material name="white"></material>
        </visual>
    </link>

    <link name="head">
        <visual>
            <geometry>
                <sphere radius="0.2"/>
            </geometry>
            <material name="white"></material>
        </visual>
        <collision>
            <geometry>
                <sphere radius="0.2"/>
            </geometry>
        </collision>
    </link>

    <joint name="base_ro_right_leg" type="fixed">
        <parent link="base_link"/>
        <child link="right_leg"/>
        <origin xyz="0 -0.22 0.25"/>
    </joint>

    <joint name="base_ro_left_leg" type="fixed">
        <parent link="base_link"/>
        <child link="left_leg"/>
        <origin xyz="0 0.22 0.25"/>
    </joint>

    <joint name="head_swivel" type="fixed">
        <parent link="base_link"/>
        <child link="head"/>
        <origin xyz="0 0 0.3"/>
    </joint>

    <link name="right_base">
        <visual>
            <geometry>
                <box size="0.4 0.1 0.1"/>
            </geometry>
            <material name="white">
                
            </material>
        </visual>
    </link>
    <joint name="right_base_joint" type="fixed">
        <parent link="right_leg"/>
        <child link="right_base"/>
        <origin xyz="0 0 -0.6"/>
        
    </joint>
    <link name="right_front_wheel">
        <visual>
            <origin rpy="1.57075 0 0" xyz="0 0 0"/>
            <geometry>
                <cylinder radius="0.1" length="0.2"/>
            </geometry>
            <material name="black">
                
            </material>
        </visual>
            <collision>
                <geometry>
                <cylinder radius="0.1" length="0.2"/>
                </geometry>
            </collision>
            <inertial>
                <mass value="0.5"/>
                <inertia ixx="0.0003" iyy="0.0003" izz="0.0003" ixy="0" ixz="0" iyz="0"/>
            </inertial>
    </link>
    <joint name="right_front_wheel_joint" type="revolute">
        <parent link="right_base"/>
        <child link="right_front_wheel"/>
        <origin rpy="0 0 0" xyz="0.133333 0 -0.085"/>
        <limit effort="10" upper="0" lower="10" velocity="1"/>
        <axis xyz="0 1 0"/>

    </joint>

    <link name="right_back_wheel">
        <visual>
            <origin rpy="1.57075 0 0" xyz="0 0 0"/>
            <geometry>
                <cylinder radius="0.1" length="0.2"/>
            </geometry>
            <material name="black">
                
            </material>
        </visual>
            <collision>
                <geometry>
                <cylinder radius="0.1" length="0.2"/>
                </geometry>
            </collision>

            <inertial>
                <mass value="0.5"/>
                <inertia ixx="0.0003" iyy="0.0003" izz="0.0003" ixy="0" ixz="0" iyz="0"/>
            </inertial>
    </link>
    <joint name="right_back_wheel_joint" type="revolute">
        <parent link="right_base"/>
        <child link="right_back_wheel"/>
        <origin rpy="0 0 0" xyz="-0.133333 0 -0.085"/>
        <limit effort="10" upper="0" lower="10" velocity="1"/>
        <axis xyz="0 1 0"/>

    </joint>

    <link name="left_base">
        <visual>
            <geometry>
                <box size="0.4 0.1 0.1"/>
            </geometry>
            <material name="white">
                
            </material>
        </visual>
    </link>
    <joint name="left_base_joint" type="fixed">
        <parent link="left_leg"/>
        <child link="left_base"/>
        <origin xyz="0 0 -0.6"/>
    </joint>
    <link name="left_front_wheel">
        <visual>
            <origin rpy="1.57075 0 0" xyz="0 0 0"/>
            <geometry>
                <cylinder radius="0.1" length="0.2"/>
            </geometry>
            <material name="black">
                
            </material>

        </visual>
            <collision>
                <geometry>
                    <cylinder radius="0.1" length="0.2"/>
                </geometry>
            </collision>

            <inertial>
                <mass value="0.5"/>
                <inertia ixx="0.0003" iyy="0.0003" izz="0.0003" ixy="0" ixz="0" iyz="0"/>
            </inertial>
    </link>
    <joint name="left_front_wheel_joint" type="revolute">
        <parent link="left_base"/>
        <child link="left_front_wheel"/>
        <origin rpy="0 0 0" xyz="0.133333 0 -0.085"/>
        <limit effort="10" upper="0" lower="10" velocity="1"/>
        <axis xyz="0 1 0"/>

    </joint>

    <link name="left_back_wheel">
        <visual>
            <origin rpy="1.57075 0 0" xyz="0 0 0"/>
            <geometry>
                <cylinder radius="0.1" length="0.2"/>
            </geometry>
            <material name="black">
                
            </material>
            
        </visual>
            <collision>
                <geometry>
                    <cylinder radius="0.1" length="0.2"/>
                </geometry>
            </collision>
            <inertial>
                <mass value="0.5"/>
                <inertia ixx="0.0003" iyy="0.0003" izz="0.0003" ixy="0" ixz="0" iyz="0"/>
            </inertial>
    </link>
    <joint name="left_back_wheel_joint" type="revolute">
        <parent link="left_base"/>
        <child link="left_back_wheel"/>
        <origin rpy="0 0 0" xyz="-0.133333 0 -0.085"/>
        <limit effort="10" upper="0" lower="10" velocity="1"/>
        <axis xyz="0 1 0"/>
    </joint>

    <link name="gripper_pole">
        <visual>
            <geometry>
                <cylinder radius="0.01" length="0.2"/>
            </geometry>
            <origin rpy="0.0 1.57075 0.0" xyz="0.1 0.0 0.0"/>
        </visual>
    </link>
    <joint name="gripper_extension" type="fixed">
        <parent link="base_link"/>
        <child link="gripper_pole"/>
        <origin rpy="0.0 0.0 0.0" xyz="0.19 0.0 0.2"/>
    </joint>
    
    <link name="left_gripper">
        <visual>
            <origin rpy="0 0 0 " xyz="0.0 0.0 0.0"/>
                 <geometry>
                     <cylinder length="0.01" radius="0.05"/>
                </geometry>
        </visual>
    </link>
    <joint name="left_gripper_joint" type="revolute">
        <origin rpy="0 0 0 " xyz="0.2 0.01 0.0"/>
        <parent link="gripper_pole"/>
        <child link="left_gripper"/>
        <limit effort="10" upper="0" lower="10" velocity="1"/>
    </joint>
    
    <link name="box">
        <visual>
            <geometry>
                <box size="0.08 0.08 0.08"/>
            </geometry>
            <material name="blue">
                
            </material>
        </visual>
    </link>
    <joint name="tobox" type="fixed">
        <parent link="head"/>
        <child link="box"/>
        <origin xyz="0.14 0.0 0.1414"/>
    </joint>


</robot>